Workbook

Sheet 1. Instructions
A1: PDF Extraction Tool Benchmark — Scoring Rubric
A2: ALPHA10X | Sourcing Assistant Document Pipeline
A4: How to use this workbook
A6: 1. Assemble a corpus of 30–50 representative PDFs covering: financial statements, pitch decks, legal docs, scanned documents, and multilingual samples. List them on the 'Corpus' sheet.
A7: 2. For each (document, tool) pair, fill in one row on the 'Per-Doc Scores' sheet. All dimensions are scored 1–5 (see scoring scale below). Yellow cells are inputs.
A8: 3. Operational metrics (throughput, memory, cost) are filled per tool on the 'Tool Profile' sheet — these are tool-level, not per-document.
A9: 4. The 'Weighted Summary' sheet aggregates per-doc scores into final weighted scores per tool. Adjust the weights column to reflect ALPHA10X priorities.
A10: 5. The 'Decision Matrix' sheet gives the final shortlist view combining quality, operational fit, and ecosystem fit.
A12: Scoring scale (1–5)
A14: 5 — Excellent: Production-ready. No meaningful errors. Output directly usable downstream.
A15: 4 — Good: Minor issues that don't affect downstream use. Occasional small fixes needed.
A16: 3 — Acceptable: Works but with noticeable errors. Usable with post-processing.
... A33: Tip: Include at least one commercial tool as a quality ceiling to calibrate whether open-source is 'good enough'.

Sheet 2. Corpus
A1: Doc ID | B1: Filename | C1: Category | D1: Pages | E1: Language | F1: Source/Notes | G1: Difficulty (1-5) | H1: Has Tables? | I1: Has Scans? | J1: Has Charts?
A2: DOC-001 | B2: 1_Rapport-financier-semestriel-AFD-2025 | C2: Financial Statement | D2: 53 | E2: English | F2: Agence Française de Développement | G2: 3 | H2: Yes | I2: No | J2: No
A3: DOC-002 | B3: 2_perfect -pitch-deck | C3: Pitch Deck / CIM | D3: 16 | E3: English | F3: Best Pitch Deck | G3: 4 | H3: No | I3: No | J3: Yes
A4: DOC-003 | B4: 3_NVCA-Model-Voting-Agreement | C4: Legal / Contract | D4: 23 | E4: English | F4: NVCA Model Legal Documents | G4: 2 | H4: No | I4: No | J4: No
A5: DOC-004 | B5: 4_scanned_document | C5: Scanned Document | D5: 10 | E5: English | F5: Internet Archive | G5: 4 | H5: Yes | I5: Yes | J5: No
A6: DOC-005 | B6: 5_ibm-annual-report-2025 | C6: Annual Report | D6: 124 | E6: English | F6: IBM Annual report | G6: 4 | H6: Yes | I6: No | J6: Yes

Sheet 3. Scoring Dimensions
A1: # | B1: Dimension | C1: What it measures | D1: How to score | E1: Score 1 (poor) | F1: Score 3 (acceptable) | G1: Score 5 (excellent) | H1: Default weight
A2: 1 | B2: Text accuracy | C2: Character/word-level fidelity of extracted text | D2: Pick 2 representative pages per doc. Compare extracted text to PDF visually OR compute CER (character error rate) against a ground-truth .txt. Score across the corpus. | E2: Many garbled characters, ligatures broken, accents lost (>5% CER) | F2: Mostly correct but occasional OCR-like errors or missing chars (~1-2% CER) | G2: Near-perfect text; ligatures, accents, special chars preserved (<0.5% CER) | H2: 10%
A3: 2 | B3: Reading order | C3: Whether multi-column, sidebars, and footnotes appear in correct logical sequence | D3: Open extracted output, read it linearly, ask: 'Does this match how a human would read the PDF?' Particularly test multi-column financial reports. | E3: Columns merged or scrambled; footnotes injected mid-paragraph | F3: Mostly correct with occasional column/sidebar confusion | G3: Perfect reading order even on complex multi-column layouts | H3: 8%
A4: 3 | B4: Table extraction — structure | C4: Whether table grid (rows, cols, merged cells, headers) is correctly recovered | D4: For each critical table, compare extracted structure to ground truth. Use TEDS (Tree Edit Distance Similarity) if automating, or visual diff if manual. Score the worst-performing table in the doc. | E4: Tables flattened to prose or completely broken | F4: Structure mostly intact; merged cells or spanning rows sometimes wrong | G4: Perfect structure including merged cells, multi-row headers, spanning | H4: 15%
A5: 4 | B5: Table extraction — content | C5: Whether numerical values inside tables are correct, including negative numbers '(123)', thousands separators, currency | D5: Spot-check 10-20 numeric cells per critical table against ground truth. Count cell-level accuracy. | E5: Numbers frequently mis-parsed (parentheses dropped, decimals shifted) | F5: Most numbers correct; occasional formatting errors | G5: All numeric values, formats, and signs preserved correctly | H5: 15%
A6: 5 | B6: Heading & structure detection | C6: Whether H1/H2/H3 hierarchy is correctly identified and preserved in output | D6: Check output for heading markers (# in markdown, level fields in JSON). Compare against actual PDF heading structure. | E6: No heading detection; flat text only | F6: Headings detected but hierarchy levels sometimes wrong | G6: Heading hierarchy matches PDF exactly | H6: 8%
A7: 6 | B7: Figures, charts & images | C7: How charts and figures are handled: extracted as images with location metadata, or attempted as structured data | D7: Check whether figures appear in output, whether captions are associated correctly, whether bounding boxes are provided. | E7: Figures lost or in wrong locations; no captions | F7: Figures extracted but captions or positions sometimes off | G7: All figures extracted with correct captions, positions, and metadata | H7: 5%
A8: 7 | B8: OCR quality (scanned docs only) | C8: Accuracy on scanned/image-based PDFs | D8: Only score on documents flagged 'Has Scans = Yes' on Corpus sheet. Same approach as text accuracy but on scanned input. | E8: Heavy OCR errors, missing chunks, gibberish on degraded scans | F8: Acceptable OCR on clean scans, struggles on degraded | G8: High accuracy even on degraded scans; language detection works | H8: 7%
A9: 8 | B9: Output format quality (for RAG) | C9: Whether output (markdown/JSON) chunks cleanly without breaking tables or losing context | D9: Try chunking the output with a standard splitter (e.g. LangChain RecursiveCharacterTextSplitter, 1000 tokens). Inspect chunks for broken tables, orphaned headings, lost structure. | E9: Markdown bloated or malformed; chunks break tables; structure lost | F9: Usable for RAG but needs custom chunking logic | G9: Clean structured output; chunks cleanly; metadata preserved | H9: 10%
A10: 9 | B10: Metadata & source attribution | C10: Page numbers, bounding boxes, source coordinates — critical for retrieval annotation back-references | D10: Inspect output schema. Does it include page numbers? Bounding boxes? Element types? | E10: No metadata; just plain text dump | F10: Page numbers present; some element typing | G10: Full metadata: page, bbox, element type, parent relationships | H10: 7%
A11: 10 | B11: Footer/header handling | C11: Whether running headers/footers/page numbers are correctly stripped or labeled | D11: Inspect output for repeated page-number noise or boilerplate injected into content. | E11: Headers/footers contaminate every page in output | F11: Inconsistent: stripped on some pages, kept on others | G11: Cleanly separated or labeled; configurable | H11: 3%
A12: 11 | B12: Multilingual support | C12: Accuracy on non-English content (esp. French for ALPHA10X) | D12: Only score on docs flagged with non-English language. Same as text accuracy but on multilingual content. | E12: Heavy errors on accented chars or non-Latin scripts | F12: Latin scripts handled; some accent errors | G12: Multiple languages including French, German, etc. with full fidelity | H12: 5%
A13: 12 | B13: Failure & edge case handling | C13: How tool behaves on malformed, password-protected, or oversized PDFs | D13: Include 2-3 'edge case' PDFs: a corrupted file, a 500-page report, a password-protected one. Score graceful degradation. | E13: Crashes, hangs, or silently produces empty output | F13: Errors out cleanly with informative messages | G13: Graceful degradation; partial output where possible; clear error reporting | H13: 7%

Sheet 4. Per-Doc Scores
A1: Doc ID | B1: Tool | C1: 1. Text accuracy | D1: 2. Reading order | E1: 3. Table structure | F1: 4. Table content | G1: 5. Heading detection | H1: 6. Figures/charts | I1: 7. OCR quality | J1: 8. RAG output quality | K1: 9. Metadata | L1: 10. Header/footer | M1: 11. Multilingual | N1: 12. Edge cases | O1: Avg (unweighted) | P1: Elapsed Time | Q1: Notes / failure modes
A2: DOC-001 | B2: PyMuPDF4llm | C2: 4 | D2: 4 | E2: 3 | F2: 3 | G2: 4 | H2: 4 | I2: N/A | J2: 3 | K2: 4 | L2: 4 | M2: N/A | N2: 3 | O2: =IFERROR(AVERAGE(C2:N2),"") -> 3.6 | P2: 77.9s | Q2: Extracted text information properly but the performance was average on extracting data from the table
A3: DOC-002 | B3: PyMuPDF4llm | C3: 3 | D3: 4 | E3: N/A | F3: N/A | G3: 4 | H3: 4 | I3: 4 | J3: 4 | K3: 5 | L3: 4 | M3: N/A | N3: 4 | O3: =IFERROR(AVERAGE(C3:N3),"") -> 4 | P3: 50.2s | Q3: Considered all the presentation slides as images. The tool gave an overall good performance
A4: DOC-003 | B4: PyMuPDF4llm | C4: 4 | D4: 5 | E4: N/A | F4: N/A | G4: 4 | H4: N/A | I4: N/A | J4: 4 | K4: 5 | L4: 4 | M4: N/A | N4: 4 | O4: =IFERROR(AVERAGE(C4:N4),"") -> 4.2857143 | P4: 18.8s | Q4: Able to extract almost exact format for a legal document
A5: DOC-004 | B5: PyMuPDF4llm | C5: 3 | D5: 3 | E5: 2 | F5: 3 | G5: 3 | H5: N/A | I5: 3 | J5: 3 | K5: 3 | L5: 3 | M5: N/A | N5: 3 | O5: =IFERROR(AVERAGE(C5:N5),"") -> 2.9 | P5: 55.7s | Q5: Difficulty in producing the data in logical sequence and the text accuracy is average. Couldn't extract data from the table in logical order.
A6: DOC-005 | B6: PyMuPDF4llm | C6: 4 | D6: 4 | E6: 4 | F6: 3 | G6: 4 | H6: 2 | I6: N/A | J6: 3 | K6: 3 | L6: 3 | M6: N/A | N6: 4 | O6: =IFERROR(AVERAGE(C6:N6),"") -> 3.4 | P6: 288.7s | Q6: Longer processing time than usual. Struggled to extract images and providing the content in logical order.
A7: DOC-001 | B7: Docling | C7: 4 | D7: 5 | E7: 5 | F7: 4 | G7: 4 | H7: 2 | I7: N/A | J7: 4 | K7: 4 | L7: 4 | M7: N/A | N7: 4 | O7: =IFERROR(AVERAGE(C7:N7),"") -> 4 | P7: 87.6s | Q7: Table structure and reading order was almost perfect. Couldn't identify and extract images properly. Took longer time to process as compared to other tools
A8: DOC-002 | B8: Docling | C8: 4 | D8: 4 | E8: N/A | F8: N/A | G8: 4 | H8: 2 | I8: 4 | J8: 4 | K8: 4 | L8: 3 | M8: N/A | N8: 3 | O8: =IFERROR(AVERAGE(C8:N8),"") -> 3.5555556 | P8: 51.6s | Q8: Was able to extract text from presentation slides. Couldn't identify and extract images.
A9: DOC-003 | B9: Docling | C9: 4 | D9: 4 | E9: N/A | F9: N/A | G9: 5 | H9: N/A | I9: N/A | J9: 4 | K9: 3 | L9: 3 | M9: N/A | N9: 4 | O9: =IFERROR(AVERAGE(C9:N9),"") -> 3.8571429 | P9: 10.3s | Q9: Difficulty in setting the output schema
A10: DOC-004 | B10: Docling | C10: 2 | D10: 3 | E10: 2 | F10: 3 | G10: 3 | H10: N/A | I10: 3 | J10: 3 | K10: 3 | L10: 2 | M10: N/A | N10: 3 | O10: =IFERROR(AVERAGE(C10:N10),"") -> 2.7 | P10: 82.6s | Q10: Able to extract text & tables from the scanned document. Difficulty in producing the data in logical sequence and the text accuracy is below average.
A11: DOC-005 | B11: Docling | C11: 4 | D11: 4 | E11: 5 | F11: 4 | G11: 4 | H11: 2 | I11: N/A | J11: 3 | K11: 4 | L11: 4 | M11: N/A | N11: 4 | O11: =IFERROR(AVERAGE(C11:N11),"") -> 3.8 | P11: 247.3s | Q11: Able to extract text and tables from the file but failed to work properly with images. Took long time to process the code.
A12: DOC-001 | B12: Unstructured | C12: 4 | D12: 4 | E12: 2 | F12: 3 | G12: 3 | H12: 2 | I12: N/A | J12: 3 | K12: 3 | L12: 3 | M12: N/A | N12: 4 | O12: =IFERROR(AVERAGE(C12:N12),"") -> 3.1 | P12: 39.9s | Q12: Preserves document hierarchy well & delivers highly accurate text extraction. Table reconstruction and visual element extraction remain weak points, requiring additional post-processing or specialized tools when working with financial reports containing complex tables and charts.
A13: DOC-002 | B13: Unstructured | C13: 1 | D13: 1 | E13: 1 | F13: 1 | G13: 1 | H13: 1 | I13: 1 | J13: 1 | K13: 2 | L13: 3 | M13: N/A | N13: 1 | O13: =IFERROR(AVERAGE(C13:N13),"") -> 1.2727273 | P13: 0.8s | Q13: Identified & extracted embedded text that existed in the PDF footer section. The presentation content was not extracted at all. Slides appear to have been processed as images without effective OCR, making the output unsuitable for search, RAG, summarization, or content analysis.
A14: DOC-003 | B14: Unstructured | C14: 4 | D14: 2 | E14: N/A | F14: N/A | G14: 3 | H14: N/A | I14: N/A | J14: 2 | K14: 3 | L14: 3 | M14: N/A | N14: 3 | O14: =IFERROR(AVERAGE(C14:N14),"") -> 2.8571429 | P14: 15.2s | Q14: Below average performance. Able to extract text but the format and logical sequence is lost.
A15: DOC-004 | B15: Unstructured | C15: 1 | D15: 1 | E15: 1 | F15: 1 | G15: 1 | H15: 1 | I15: 1 | J15: 1 | K15: 1 | L15: 1 | M15: N/A | N15: 1 | O15: =IFERROR(AVERAGE(C15:N15),"") -> 1 | P15: 3.4s | Q15: Couldn't identify and extract text from the scanned document. It was able to extract only the watermark.
A16: DOC-005 | B16: Unstructured | C16: 3 | D16: 2 | E16: 2 | F16: 3 | G16: 3 | H16: 2 | I16: N/A | J16: 2 | K16: 2 | L16: 3 | M16: N/A | N16: 3 | O16: =IFERROR(AVERAGE(C16:N16),"") -> 2.5 | P16: 149.4s | Q16: Couldn't extract texts and tables properly from the file. Reading order was poor.
A17: DOC-001 | B17: Open Data Loader | C17: 4 | D17: 5 | E17: 2 | F17: 4 | G17: 4 | H17: 3 | I17: N/A | J17: 4 | K17: 3 | L17: 3 | M17: N/A | N17: 4 | O17: =IFERROR(AVERAGE(C17:N17),"") -> 3.6 | P17: 20.8s | Q17: Good performance in extracting the text and table content but the table structure was almost broken. Had difficulty in extracting all the figures from the file
A18: DOC-002 | B18: Open Data Loader | C18: 1 | D18: 3 | E18: 1 | F18: 1 | G18: 2 | H18: 2 | I18: 1 | J18: 1 | K18: 2 | L18: 2 | M18: N/A | N18: 2 | O18: =IFERROR(AVERAGE(C18:N18),"") -> 1.6363636 | P18: 10.9s | Q18: Correctly identified individual slides and preserved the slide sequence. It also extracted the text from the final slide accurately, including footer and copyright information. The actual slide content was not extracted, leaving only image placeholders for most pages.
A19: DOC-003 | B19: Open Data Loader | C19: 5 | D19: 4 | E19: N/A | F19: N/A | G19: 3 | H19: N/A | I19: N/A | J19: 4 | K19: 4 | L19: 4 | M19: N/A | N19: 4 | O19: =IFERROR(AVERAGE(C19:N19),"") -> 4 | P19: 6.6s | Q19: Extracted content well from the pdf and maintained the reading order. There was no images and table in the document.
A20: DOC-004 | B20: Open Data Loader | C20: 1 | D20: 2 | E20: 1 | F20: 1 | G20: 1 | H20: 2 | I20: 1 | J20: 1 | K20: 2 | L20: 2 | M20: N/A | N20: 2 | O20: =IFERROR(AVERAGE(C20:N20),"") -> 1.4545455 | P20: 11.0s | Q20: Identified image boundaries and preserved document pagination. OCR extraction failed completely on the document content, capturing only the repeated watermark text.
A21: DOC-005 | B21: Open Data Loader | C21: 4 | D21: 3 | E21: 2 | F21: 4 | G21: 4 | H21: 3 | I21: N/A | J21: 3 | K21: 3 | L21: 3 | M21: N/A | N21: 3 | O21: =IFERROR(AVERAGE(C21:N21),"") -> 3.2 | P21: 20.4s | Q21: Able to extract text and table content from the pdf. Faced difficulty in finding the reading order and table structure was broken where there was multiple merged cells
A22: DOC-001 | B22: marker | C22: 3 | D22: 4 | E22: 4 | F22: 4 | G22: 4 | H22: 4 | I22: N/A | J22: 3 | K22: 4 | L22: 4 | M22: N/A | N22: 4 | O22: =IFERROR(AVERAGE(C22:N22),"") -> 3.8 | P22: 122.8s | Q22: Was able to extract text, tables & images from the document. Failed to extract page numbers and headers.
A23: DOC-002 | B23: marker | C23: 3 | D23: 2 | E23: N/A | F23: N/A | G23: 3 | H23: 2 | I23: 3 | J23: 3 | K23: 3 | L23: 3 | M23: N/A | N23: 3 | O23: =IFERROR(AVERAGE(C23:N23),"") -> 2.7777778 | P23: 111.6s | Q23: Able to extract text along with layout metadata like bounding boxes. Reading order & document structure are not reliable and weak reconstruction of complex layouts
A24: DOC-003 | B24: marker | C24: 4 | D24: 4 | E24: N/A | F24: N/A | G24: 4 | H24: N/A | I24: N/A | J24: 4 | K24: 4 | L24: 4 | M24: N/A | N24: 4 | O24: =IFERROR(AVERAGE(C24:N24),"") -> 4 | P24: 24.9s | Q24: Able to extract text including headings, footnotes, and hierarchical sections. Was able to preserve reading order in most sections, but complex formatting is inconsistently aligned.
A25: DOC-004 | B25: marker | C25: 3 | D25: 3 | E25: 2 | F25: 2 | G25: 3 | H25: 2 | I25: 3 | J25: 3 | K25: 4 | L25: 3 | M25: N/A | N25: 3 | O25: =IFERROR(AVERAGE(C25:N25),"") -> 2.8181818 | P25: 85.4s | Q25: Extracts strong structural metadata and decent raw text. Struggles with tables, figures, & maintaining correct reading order, especially in scanned documents.
A26: DOC-005 | B26: marker | C26: 5 | D26: 4 | E26: 4 | F26: 5 | G26: 5 | H26: 4 | I26: N/A | J26: 4 | K26: 4 | L26: 4 | M26: N/A | N26: 4 | O26: =IFERROR(AVERAGE(C26:N26),"") -> 4.3 | P26: 218.7s | Q26: Nearly accurate text extraction and heading hierarchy. It struggled a little in reading order consistency in mixed-layout pages (tables + figures + narrative)
A27: DOC-001 | B27: pdftotext + pymupdf | C27: 5 | D27: 5 | E27: 5 | F27: 4 | G27: 2 | H27: 3 | I27: N/A | J27: 4 | K27: 4 | L27: 4 | M27: N/A | N27: 4 | O27: =IFERROR(AVERAGE(C27:N27),"") -> 4 | P27: 13.3s | Q27: Near perfect response in extracting text and tables. Reading order and logical sequence is maintained.
A28: DOC-002 | B28: pdftotext + pymupdf | C28: 4 | D28: 3 | E28: N/A | F28: N/A | G28: 2 | H28: 3 | I28: 3 | J28: 3 | K28: 3 | L28: 3 | M28: N/A | N28: 3 | O28: =IFERROR(AVERAGE(C28:N28),"") -> 3 | P28: 48.9s | Q28: Average performance for a presentation document. Took longer time to process and couldn't present the data in proper reading order. Also, some data weren't extracted.
A29: DOC-003 | B29: pdftotext + pymupdf | C29: 4 | D29: 5 | E29: N/A | F29: N/A | G29: 2 | H29: N/A | I29: N/A | J29: 4 | K29: 4 | L29: 4 | M29: N/A | N29: 4 | O29: =IFERROR(AVERAGE(C29:N29),"") -> 3.8571429 | P29: 4.1s | Q29: Works well for the legal document. Able to extract the format and data of the provided document
A30: DOC-004 | B30: pdftotext + pymupdf | C30: 4 | D30: 3 | E30: 2 | F30: 3 | G30: 2 | H30: N/A | I30: 3 | J30: 3 | K30: 3 | L30: 3 | M30: N/A | N30: 3 | O30: =IFERROR(AVERAGE(C30:N30),"") -> 2.9 | P30: 131.0s | Q30: Able to extract text & tables from the scanned document. Difficulty in producing the data in logical sequence and the text accuracy is below average.
A31: DOC-005 | B31: pdftotext + pymupdf | C31: 4 | D31: 4 | E31: 4 | F31: 4 | G31: 2 | H31: 2 | I31: N/A | J31: 4 | K31: 4 | L31: 4 | M31: N/A | N31: 4 | O31: =IFERROR(AVERAGE(C31:N31),"") -> 3.6 | P31: 24.3s | Q31: Difficulty in identifying the figures and charts. the header identification is absent.
A32: DOC-001 | B32: pdftotext + docling | C32: 4 | D32: 3 | E32: 3 | F32: 4 | G32: 4 | H32: 3 | I32: N/A | J32: 4 | K32: 3 | L32: 3 | M32: N/A | N32: 4 | O32: =IFERROR(AVERAGE(C32:N32),"") -> 3.5 | P32: 146.0s | Q32: Well extracted the text, numerical values and section hierarchy from the pdf. Had difficulty with table layout, figures and incomplete reading-order reconstruction.
A33: DOC-002 | B33: pdftotext + docling | C33: 3 | D33: 3 | E33: N/A | F33: N/A | G33: 3 | H33: 4 | I33: 4 | J33: 3 | K33: 3 | L33: 3 | M33: N/A | N33: 3 | O33: =IFERROR(AVERAGE(C33:N33),"") -> 3.2222222 | P33: 122.6s | Q33: Average extraction of data from the document. Reading order was maintained with few missing visual content. Also, the output schema lacked page numbers and footers.
A34: DOC-003 | B34: pdftotext + docling | C34: 4 | D34: 4 | E34: N/A | F34: N/A | G34: 4 | H34: N/A | I34: N/A | J34: 4 | K34: 3 | L34: 4 | M34: N/A | N34: 4 | O34: =IFERROR(AVERAGE(C34:N34),"") -> 3.8571429 | P34: 106.0s | Q34: Extracted major data accurately from the legal document. Was able to capture the logical sequence and formatting intent.
A35: DOC-004 | B35: pdftotext + docling | C35: 3 | D35: 3 | E35: 3 | F35: 3 | G35: 4 | H35: N/A | I35: 3 | J35: 3 | K35: 3 | L35: 3 | M35: N/A | N35: 3 | O35: =IFERROR(AVERAGE(C35:N35),"") -> 3.1 | P35: 200.0s | Q35: Moderate level extraction for structured form documents and able to preserve section flow, checkboxes. Could observe table misalignment which results in low-level accuracy.
A36: DOC-005 | B36: pdftotext + docling | C36: 4 | D36: 3 | E36: 4 | F36: 4 | G36: 4 | H36: 3 | I36: N/A | J36: 4 | K36: 3 | L36: 3 | M36: N/A | N36: 4 | O36: =IFERROR(AVERAGE(C36:N36),"") -> 3.6 | P36: 144.9s | Q36: Able to extract most of the text, headings, and tables. It has difficulty with multi-column layouts, charts and repeated page elements.
A37: DOC-001 | B37: Llamaparse | C37: 5 | D37: 5 | E37: 5 | F37: 4 | G37: 5 | H37: 4 | I37: N/A | J37: 5 | K37: 4 | L37: 4 | M37: N/A | N37: 4 | O37: =IFERROR(AVERAGE(C37:N37),"") -> 4.5 | P37: 64.5s | Q37: Able to preserves document's logical structure exceptionally well, like heading hierarchy, page boundaries, footnotes, and section organization. There is very minimal formatting loss.
A38: DOC-002 | B38: Llamaparse | C38: 5 | D38: 5 | E38: N/A | F38: N/A | G38: 4 | H38: 4 | I38: 3 | J38: 4 | K38: 4 | L38: 3 | M38: N/A | N38: 4 | O38: =IFERROR(AVERAGE(C38:N38),"") -> 4 | P38: 78.2s | Q38: Preserved slide structure accurately. Captured headings, bullet points, emphasis, callouts, and page breaks. Maintained presentation semantics better than other solutions.
A39: DOC-003 | B39: Llamaparse | C39: 5 | D39: 5 | E39: N/A | F39: N/A | G39: 4 | H39: N/A | I39: N/A | J39: 4 | K39: 5 | L39: 4 | M39: N/A | N39: 4 | O39: =IFERROR(AVERAGE(C39:N39),"") -> 4.4285714 | P39: 48.6s | Q39: Extracted complex legal formatting, numbered clauses, definitions, recitals, and footnotes effectively. Maintained logical document flow and hierarchy.
A40: DOC-004 | B40: Llamaparse | C40: 4 | D40: 4 | E40: 5 | F40: 4 | G40: 5 | H40: N/A | I40: 4 | J40: 4 | K40: 3 | L40: 4 | M40: N/A | N40: 4 | O40: =IFERROR(AVERAGE(C40:N40),"") -> 4.1 | P40: 52.7s | Q40: Successfully extracted field labels, tables, checkbox states, personal details, and incident information while maintaining document organization. Compared with legal agreements and financial reports, form documents are inherently more difficult because of their grid-based layouts, merged cells, and checkbox controls. The output remains highly usable with only minor OCR errors like misspelled words, Corrupted field values.
...

Sheet 5. Weights
A1: Dimension weights
A2: Adjust the weight column to reflect ALPHA10X priorities. Weights should sum to 100%.
A4: # | B4: Dimension | C4: Weight | D4: Rationale
A5: 1 | B5: Text accuracy | C5: 0.1 | D5: Foundation but most tools are now decent here.
A6: 2 | B6: Reading order | C6: 0.08 | D6: Critical for multi-column financial reports.
A7: 3 | B7: Table structure | C7: 0.15 | D7: PE use case: financials, comps tables are core data.
A8: 4 | B8: Table content | C8: 0.15 | D8: Numerical fidelity drives downstream analysis quality.
A9: 5 | B9: Heading detection | C9: 0.08 | D9: Drives chunking and section-level retrieval.
A10: 6 | B10: Figures/charts | C10: 0.05 | D10: Less critical if charts are kept as images.
A11: 7 | B11: OCR quality | C11: 0.07 | D11: Needed when CIMs/teasers arrive as scans.
A12: 8 | B12: RAG output quality | C12: 0.1 | D12: Directly affects assistant retrieval quality.
A13: 9 | B13: Metadata | C13: 0.07 | D13: Needed for retrieval annotation framework source attribution.
A14: 10 | B14: Header/footer | C14: 0.03 | D14: Nuisance, not blocker — post-processable.
A15: 11 | B15: Multilingual | C15: 0.05 | D15: French content at ALPHA10X.
A16: 12 | B16: Edge cases | C16: 0.07 | D16: Production robustness.
B17: TOTAL | C17: =SUM(C5:C16) -> 1

Sheet 6. Weighted Summary
A1: Per-tool weighted scores (averaged across corpus)
A2: Add tool names in column A. Cells compute the AVG score per dimension across all corpus docs for that tool, then apply weights from sheet '5. Weights'.
A4: Tool | B4: D1: Text | C4: D2: Read order | D4: D3: Tbl struct | E4: D4: Tbl content | F4: D5: Heading | G4: D6: Figures | H4: D7: OCR | I4: D8: RAG out | J4: D9: Metadata | K4: D10: H/F | L4: D11: Multiling | M4: D12: Edge | N4: Weighted score | O4: Rank
A5: Pymupdf4llm | B5: =IFERROR(AVERAGEIFS('4. Per-Doc Scores'!C:C,'4. Per-Doc Scores'!B:B,A5),"") -> 3.6 | C5: =IFERROR(AVERAGEIFS('4. Per-Doc Scores'!D:D,'4. Per-Doc Scores'!B:B,A5),"") -> 4 | D5: =IFERROR(AVERAGEIFS('4. Per-Doc Scores'!E:E,'4. Per-Doc Scores'!B:B,A5),"") -> 3 | E5: =IFERROR(AVERAGEIFS('4. Per-Doc Scores'!F:F,'4. Per-Doc Scores'!B:B,A5),"") -> 3 | F5: =IFERROR(AVERAGEIFS('4. Per-Doc Scores'!G:G,'4. Per-Doc Scores'!B:B,A5),"") -> 3.8 | G5: =IFERROR(AVERAGEIFS('4. Per-Doc Scores'!H:H,'4. Per-Doc Scores'!B:B,A5),"") -> 3.3333333 | H5: =IFERROR(AVERAGEIFS('4. Per-Doc Scores'!I:I,'4. Per-Doc Scores'!B:B,A5),"") -> 3.5 | I5: =IFERROR(AVERAGEIFS('4. Per-Doc Scores'!J:J,'4. Per-Doc Scores'!B:B,A5),"") -> 3.4 | J5: =IFERROR(AVERAGEIFS('4. Per-Doc Scores'!K:K,'4. Per-Doc Scores'!B:B,A5),"") -> 4 | K5: =IFERROR(AVERAGEIFS('4. Per-Doc Scores'!L:L,'4. Per-Doc Scores'!B:B,A5),"") -> 3.6 | L5: 0 | M5: =IFERROR(AVERAGEIFS('4. Per-Doc Scores'!N:N,'4. Per-Doc Scores'!B:B,A5),"") -> 3.6 | N5: 3.27 | O5: =IFERROR(RANK(N5,$N$5:$N$13),"") -> 7
A6: Docling | B6: =IFERROR(AVERAGEIFS('4. Per-Doc Scores'!C:C,'4. Per-Doc Scores'!B:B,A6),"") -> 3.6 | C6: =IFERROR(AVERAGEIFS('4. Per-Doc Scores'!D:D,'4. Per-Doc Scores'!B:B,A6),"") -> 4 | D6: =IFERROR(AVERAGEIFS('4. Per-Doc Scores'!E:E,'4. Per-Doc Scores'!B:B,A6),"") -> 4 | E6: =IFERROR(AVERAGEIFS('4. Per-Doc Scores'!F:F,'4. Per-Doc Scores'!B:B,A6),"") -> 3.6666667 | F6: =IFERROR(AVERAGEIFS('4. Per-Doc Scores'!G:G,'4. Per-Doc Scores'!B:B,A6),"") -> 4 | G6: =IFERROR(AVERAGEIFS('4. Per-Doc Scores'!H:H,'4. Per-Doc Scores'!B:B,A6),"") -> 2 | H6: =IFERROR(AVERAGEIFS('4. Per-Doc Scores'!I:I,'4. Per-Doc Scores'!B:B,A6),"") -> 3.5 | I6: =IFERROR(AVERAGEIFS('4. Per-Doc Scores'!J:J,'4. Per-Doc Scores'!B:B,A6),"") -> 3.6 | J6: =IFERROR(AVERAGEIFS('4. Per-Doc Scores'!K:K,'4. Per-Doc Scores'!B:B,A6),"") -> 3.6 | K6: =IFERROR(AVERAGEIFS('4. Per-Doc Scores'!L:L,'4. Per-Doc Scores'!B:B,A6),"") -> 3.2 | L6: 0 | M6: =IFERROR(AVERAGEIFS('4. Per-Doc Scores'!N:N,'4. Per-Doc Scores'!B:B,A6),"") -> 3.6 | N6: 3.45 | O6: =IFERROR(RANK(N6,$N$5:$N$13),"") -> 2
A7: Unstructured | B7: =IFERROR(AVERAGEIFS('4. Per-Doc Scores'!C:C,'4. Per-Doc Scores'!B:B,A7),"") -> 2.6 | C7: =IFERROR(AVERAGEIFS('4. Per-Doc Scores'!D:D,'4. Per-Doc Scores'!B:B,A7),"") -> 2 | D7: =IFERROR(AVERAGEIFS('4. Per-Doc Scores'!E:E,'4. Per-Doc Scores'!B:B,A7),"") -> 1.5 | E7: =IFERROR(AVERAGEIFS('4. Per-Doc Scores'!F:F,'4. Per-Doc Scores'!B:B,A7),"") -> 2 | F7: =IFERROR(AVERAGEIFS('4. Per-Doc Scores'!G:G,'4. Per-Doc Scores'!B:B,A7),"") -> 2.2 | G7: =IFERROR(AVERAGEIFS('4. Per-Doc Scores'!H:H,'4. Per-Doc Scores'!B:B,A7),"") -> 1.5 | H7: =IFERROR(AVERAGEIFS('4. Per-Doc Scores'!I:I,'4. Per-Doc Scores'!B:B,A7),"") -> 1 | I7: =IFERROR(AVERAGEIFS('4. Per-Doc Scores'!J:J,'4. Per-Doc Scores'!B:B,A7),"") -> 1.8 | J7: =IFERROR(AVERAGEIFS('4. Per-Doc Scores'!K:K,'4. Per-Doc Scores'!B:B,A7),"") -> 2.2 | K7: =IFERROR(AVERAGEIFS('4. Per-Doc Scores'!L:L,'4. Per-Doc Scores'!B:B,A7),"") -> 2.6 | L7: 0 | M7: =IFERROR(AVERAGEIFS('4. Per-Doc Scores'!N:N,'4. Per-Doc Scores'!B:B,A7),"") -> 2.4 | N7: 1.85 | O7: =IFERROR(RANK(N7,$N$5:$N$13),"") -> 9
A8: Open Data Loader | B8: =IFERROR(AVERAGEIFS('4. Per-Doc Scores'!C:C,'4. Per-Doc Scores'!B:B,A8),"") -> 3 | C8: =IFERROR(AVERAGEIFS('4. Per-Doc Scores'!D:D,'4. Per-Doc Scores'!B:B,A8),"") -> 3.4 | D8: =IFERROR(AVERAGEIFS('4. Per-Doc Scores'!E:E,'4. Per-Doc Scores'!B:B,A8),"") -> 1.5 | E8: =IFERROR(AVERAGEIFS('4. Per-Doc Scores'!F:F,'4. Per-Doc Scores'!B:B,A8),"") -> 2.5 | F8: =IFERROR(AVERAGEIFS('4. Per-Doc Scores'!G:G,'4. Per-Doc Scores'!B:B,A8),"") -> 2.8 | G8: =IFERROR(AVERAGEIFS('4. Per-Doc Scores'!H:H,'4. Per-Doc Scores'!B:B,A8),"") -> 2.5 | H8: =IFERROR(AVERAGEIFS('4. Per-Doc Scores'!I:I,'4. Per-Doc Scores'!B:B,A8),"") -> 1 | I8: =IFERROR(AVERAGEIFS('4. Per-Doc Scores'!J:J,'4. Per-Doc Scores'!B:B,A8),"") -> 2.6 | J8: =IFERROR(AVERAGEIFS('4. Per-Doc Scores'!K:K,'4. Per-Doc Scores'!B:B,A8),"") -> 2.8 | K8: =IFERROR(AVERAGEIFS('4. Per-Doc Scores'!L:L,'4. Per-Doc Scores'!B:B,A8),"") -> 2.8 | L8: 0 | M8: =IFERROR(AVERAGEIFS('4. Per-Doc Scores'!N:N,'4. Per-Doc Scores'!B:B,A8),"") -> 3 | N8: 2.34 | O8: =IFERROR(RANK(N8,$N$5:$N$13),"") -> 8
A9: Marker | B9: =IFERROR(AVERAGEIFS('4. Per-Doc Scores'!C:C,'4. Per-Doc Scores'!B:B,A9),"") -> 3.6 | C9: =IFERROR(AVERAGEIFS('4. Per-Doc Scores'!D:D,'4. Per-Doc Scores'!B:B,A9),"") -> 3.4 | D9: =IFERROR(AVERAGEIFS('4. Per-Doc Scores'!E:E,'4. Per-Doc Scores'!B:B,A9),"") -> 3.3333333 | E9: =IFERROR(AVERAGEIFS('4. Per-Doc Scores'!F:F,'4. Per-Doc Scores'!B:B,A9),"") -> 3.6666667 | F9: =IFERROR(AVERAGEIFS('4. Per-Doc Scores'!G:G,'4. Per-Doc Scores'!B:B,A9),"") -> 3.8 | G9: =IFERROR(AVERAGEIFS('4. Per-Doc Scores'!H:H,'4. Per-Doc Scores'!B:B,A9),"") -> 3 | H9: =IFERROR(AVERAGEIFS('4. Per-Doc Scores'!I:I,'4. Per-Doc Scores'!B:B,A9),"") -> 3 | I9: =IFERROR(AVERAGEIFS('4. Per-Doc Scores'!J:J,'4. Per-Doc Scores'!B:B,A9),"") -> 3.4 | J9: =IFERROR(AVERAGEIFS('4. Per-Doc Scores'!K:K,'4. Per-Doc Scores'!B:B,A9),"") -> 3.8 | K9: =IFERROR(AVERAGEIFS('4. Per-Doc Scores'!L:L,'4. Per-Doc Scores'!B:B,A9),"") -> 3.6 | L9: 0 | M9: =IFERROR(AVERAGEIFS('4. Per-Doc Scores'!N:N,'4. Per-Doc Scores'!B:B,A9),"") -> 3.6 | N9: 3.32 | O9: =IFERROR(RANK(N9,$N$5:$N$13),"") -> 4
A10: pdftotext + pymupdf | B10: =IFERROR(AVERAGEIFS('4. Per-Doc Scores'!C:C,'4. Per-Doc Scores'!B:B,A10),"") -> 4.2 | C10: =IFERROR(AVERAGEIFS('4. Per-Doc Scores'!D:D,'4. Per-Doc Scores'!B:B,A10),"") -> 4 | D10: =IFERROR(AVERAGEIFS('4. Per-Doc Scores'!E:E,'4. Per-Doc Scores'!B:B,A10),"") -> 3.6666667 | E10: =IFERROR(AVERAGEIFS('4. Per-Doc Scores'!F:F,'4. Per-Doc Scores'!B:B,A10),"") -> 3.6666667 | F10: =IFERROR(AVERAGEIFS('4. Per-Doc Scores'!G:G,'4. Per-Doc Scores'!B:B,A10),"") -> 2 | G10: =IFERROR(AVERAGEIFS('4. Per-Doc Scores'!H:H,'4. Per-Doc Scores'!B:B,A10),"") -> 2.6666667 | H10: =IFERROR(AVERAGEIFS('4. Per-Doc Scores'!I:I,'4. Per-Doc Scores'!B:B,A10),"") -> 3 | I10: =IFERROR(AVERAGEIFS('4. Per-Doc Scores'!J:J,'4. Per-Doc Scores'!B:B,A10),"") -> 3.6 | J10: =IFERROR(AVERAGEIFS('4. Per-Doc Scores'!K:K,'4. Per-Doc Scores'!B:B,A10),"") -> 3.6 | K10: =IFERROR(AVERAGEIFS('4. Per-Doc Scores'!L:L,'4. Per-Doc Scores'!B:B,A10),"") -> 3.6 | L10: 0 | M10: =IFERROR(AVERAGEIFS('4. Per-Doc Scores'!N:N,'4. Per-Doc Scores'!B:B,A10),"") -> 3.6 | N10: 3.31 | O10: =IFERROR(RANK(N10,$N$5:$N$13),"") -> 5
A11: pdftotext + docling | B11: =IFERROR(AVERAGEIFS('4. Per-Doc Scores'!C:C,'4. Per-Doc Scores'!B:B,A11),"") -> 3.6 | C11: =IFERROR(AVERAGEIFS('4. Per-Doc Scores'!D:D,'4. Per-Doc Scores'!B:B,A11),"") -> 3.2 | D11: =IFERROR(AVERAGEIFS('4. Per-Doc Scores'!E:E,'4. Per-Doc Scores'!B:B,A11),"") -> 3.3333333 | E11: =IFERROR(AVERAGEIFS('4. Per-Doc Scores'!F:F,'4. Per-Doc Scores'!B:B,A11),"") -> 3.6666667 | F11: =IFERROR(AVERAGEIFS('4. Per-Doc Scores'!G:G,'4. Per-Doc Scores'!B:B,A11),"") -> 3.8 | G11: =IFERROR(AVERAGEIFS('4. Per-Doc Scores'!H:H,'4. Per-Doc Scores'!B:B,A11),"") -> 3.3333333 | H11: =IFERROR(AVERAGEIFS('4. Per-Doc Scores'!I:I,'4. Per-Doc Scores'!B:B,A11),"") -> 3.5 | I11: =IFERROR(AVERAGEIFS('4. Per-Doc Scores'!J:J,'4. Per-Doc Scores'!B:B,A11),"") -> 3.6 | J11: =IFERROR(AVERAGEIFS('4. Per-Doc Scores'!K:K,'4. Per-Doc Scores'!B:B,A11),"") -> 3 | K11: =IFERROR(AVERAGEIFS('4. Per-Doc Scores'!L:L,'4. Per-Doc Scores'!B:B,A11),"") -> 3.2 | L11: 0 | M11: =IFERROR(AVERAGEIFS('4. Per-Doc Scores'!N:N,'4. Per-Doc Scores'!B:B,A11),"") -> 3.6 | N11: 3.29 | O11: =IFERROR(RANK(N11,$N$5:$N$13),"") -> 6
A12: Llamaparse | B12: =IFERROR(AVERAGEIFS('4. Per-Doc Scores'!C:C,'4. Per-Doc Scores'!B:B,A12),"") -> 4.8 | C12: =IFERROR(AVERAGEIFS('4. Per-Doc Scores'!D:D,'4. Per-Doc Scores'!B:B,A12),"") -> 4.6 | D12: =IFERROR(AVERAGEIFS('4. Per-Doc Scores'!E:E,'4. Per-Doc Scores'!B:B,A12),"") -> 4.6666667 | E12: =IFERROR(AVERAGEIFS('4. Per-Doc Scores'!F:F,'4. Per-Doc Scores'!B:B,A12),"") -> 4 | F12: =IFERROR(AVERAGEIFS('4. Per-Doc Scores'!G:G,'4. Per-Doc Scores'!B:B,A12),"") -> 4.4 | G12: =IFERROR(AVERAGEIFS('4. Per-Doc Scores'!H:H,'4. Per-Doc Scores'!B:B,A12),"") -> 3.6666667 | H12: =IFERROR(AVERAGEIFS('4. Per-Doc Scores'!I:I,'4. Per-Doc Scores'!B:B,A12),"") -> 3.5 | I12: =IFERROR(AVERAGEIFS('4. Per-Doc Scores'!J:J,'4. Per-Doc Scores'!B:B,A12),"") -> 4.2 | J12: =IFERROR(AVERAGEIFS('4. Per-Doc Scores'!K:K,'4. Per-Doc Scores'!B:B,A12),"") -> 4 | K12: =IFERROR(AVERAGEIFS('4. Per-Doc Scores'!L:L,'4. Per-Doc Scores'!B:B,A12),"") -> 3.8 | L12: 0 | M12: =IFERROR(AVERAGEIFS('4. Per-Doc Scores'!N:N,'4. Per-Doc Scores'!B:B,A12),"") -> 4 | N12: 4.02 | O12: =IFERROR(RANK(N12,$N$5:$N$13),"") -> 1
A13: Azure Document Intelligence | B13: =IFERROR(AVERAGEIFS('4. Per-Doc Scores'!C:C,'4. Per-Doc Scores'!B:B,A13),"") -> 4 | C13: =IFERROR(AVERAGEIFS('4. Per-Doc Scores'!D:D,'4. Per-Doc Scores'!B:B,A13),"") -> 3.8 | D13: =IFERROR(AVERAGEIFS('4. Per-Doc Scores'!E:E,'4. Per-Doc Scores'!B:B,A13),"") -> 3.25 | E13: =IFERROR(AVERAGEIFS('4. Per-Doc Scores'!F:F,'4. Per-Doc Scores'!B:B,A13),"") -> 4 | F13: =IFERROR(AVERAGEIFS('4. Per-Doc Scores'!G:G,'4. Per-Doc Scores'!B:B,A13),"") -> 3.4 | G13: =IFERROR(AVERAGEIFS('4. Per-Doc Scores'!H:H,'4. Per-Doc Scores'!B:B,A13),"") -> 3 | H13: =IFERROR(AVERAGEIFS('4. Per-Doc Scores'!I:I,'4. Per-Doc Scores'!B:B,A13),"") -> 3 | I13: =IFERROR(AVERAGEIFS('4. Per-Doc Scores'!J:J,'4. Per-Doc Scores'!B:B,A13),"") -> 3.4 | J13: =IFERROR(AVERAGEIFS('4. Per-Doc Scores'!K:K,'4. Per-Doc Scores'!B:B,A13),"") -> 3.6 | K13: =IFERROR(AVERAGEIFS('4. Per-Doc Scores'!L:L,'4. Per-Doc Scores'!B:B,A13),"") -> 3.8 | L13: 0 | M13: =IFERROR(AVERAGEIFS('4. Per-Doc Scores'!N:N,'4. Per-Doc Scores'!B:B,A13),"") -> 3.4 | N13: 3.36 | O13: =IFERROR(RANK(N13,$N$5:$N$13),"") -> 3
B14: =IFERROR(AVERAGEIFS('4. Per-Doc Scores'!C:C,'4. Per-Doc Scores'!B:B,A14),"") | C14: =IFERROR(AVERAGEIFS('4. Per-Doc Scores'!D:D,'4. Per-Doc Scores'!B:B,A14),"") | D14: =IFERROR(AVERAGEIFS('4. Per-Doc Scores'!E:E,'4. Per-Doc Scores'!B:B,A14),"") | E14: =IFERROR(AVERAGEIFS('4. Per-Doc Scores'!F:F,'4. Per-Doc Scores'!B:B,A14),"") | F14: =IFERROR(AVERAGEIFS('4. Per-Doc Scores'!G:G,'4. Per-Doc Scores'!B:B,A14),"") | G14: =IFERROR(AVERAGEIFS('4. Per-Doc Scores'!H:H,'4. Per-Doc Scores'!B:B,A14),"") | H14: =IFERROR(AVERAGEIFS('4. Per-Doc Scores'!I:I,'4. Per-Doc Scores'!B:B,A14),"") | I14: =IFERROR(AVERAGEIFS('4. Per-Doc Scores'!J:J,'4. Per-Doc Scores'!B:B,A14),"") | J14: =IFERROR(AVERAGEIFS('4. Per-Doc Scores'!K:K,'4. Per-Doc Scores'!B:B,A14),"") | K14: =IFERROR(AVERAGEIFS('4. Per-Doc Scores'!L:L,'4. Per-Doc Scores'!B:B,A14),"") | L14: =IFERROR(AVERAGEIFS('4. Per-Doc Scores'!M:M,'4. Per-Doc Scores'!B:B,A14),"") | M14: =IFERROR(AVERAGEIFS('4. Per-Doc Scores'!N:N,'4. Per-Doc Scores'!B:B,A14),"") | N14: =IFERROR(SUMPRODUCT(IFERROR(B14:M14,0),'5. Weights'!C10:C21),"") | O14: =IFERROR(RANK(N14,$N$5:$N$10),"")
B15: =IFERROR(AVERAGEIFS('4. Per-Doc Scores'!C:C,'4. Per-Doc Scores'!B:B,A15),"") | C15: =IFERROR(AVERAGEIFS('4. Per-Doc Scores'!D:D,'4. Per-Doc Scores'!B:B,A15),"") | D15: =IFERROR(AVERAGEIFS('4. Per-Doc Scores'!E:E,'4. Per-Doc Scores'!B:B,A15),"") | E15: =IFERROR(AVERAGEIFS('4. Per-Doc Scores'!F:F,'4. Per-Doc Scores'!B:B,A15),"") | F15: =IFERROR(AVERAGEIFS('4. Per-Doc Scores'!G:G,'4. Per-Doc Scores'!B:B,A15),"") | G15: =IFERROR(AVERAGEIFS('4. Per-Doc Scores'!H:H,'4. Per-Doc Scores'!B:B,A15),"") | H15: =IFERROR(AVERAGEIFS('4. Per-Doc Scores'!I:I,'4. Per-Doc Scores'!B:B,A15),"") | I15: =IFERROR(AVERAGEIFS('4. Per-Doc Scores'!J:J,'4. Per-Doc Scores'!B:B,A15),"") | J15: =IFERROR(AVERAGEIFS('4. Per-Doc Scores'!K:K,'4. Per-Doc Scores'!B:B,A15),"") | K15: =IFERROR(AVERAGEIFS('4. Per-Doc Scores'!L:L,'4. Per-Doc Scores'!B:B,A15),"") | L15: =IFERROR(AVERAGEIFS('4. Per-Doc Scores'!M:M,'4. Per-Doc Scores'!B:B,A15),"") | M15: =IFERROR(AVERAGEIFS('4. Per-Doc Scores'!N:N,'4. Per-Doc Scores'!B:B,A15),"") | N15: =IFERROR(SUMPRODUCT(IFERROR(B15:M15,0),'5. Weights'!C11:C22),"") | O15: =IFERROR(RANK(N15,$N$5:$N$10),"")

Sheet 7. Decision Matrix
A1: Final decision matrix
A5: Tool | B5: Quality (0-5) | C5: Rank
A6: ='6. Weighted Summary'!A5 -> Pymupdf4llm | B6: =IFERROR('6. Weighted Summary'!N5,"") -> 3.27 | C6: 7
A7: ='6. Weighted Summary'!A6 -> Docling | B7: =IFERROR('6. Weighted Summary'!N6,"") -> 3.45 | C7: 2
A8: ='6. Weighted Summary'!A7 -> Unstructured | B8: =IFERROR('6. Weighted Summary'!N7,"") -> 1.85 | C8: 9
A9: ='6. Weighted Summary'!A8 -> Open Data Loader | B9: =IFERROR('6. Weighted Summary'!N8,"") -> 2.34 | C9: 8
A10: ='6. Weighted Summary'!A9 -> Marker | B10: =IFERROR('6. Weighted Summary'!N9,"") -> 3.32 | C10: 4
A11: ='6. Weighted Summary'!A10 -> pdftotext + pymupdf | B11: =IFERROR('6. Weighted Summary'!N10,"") -> 3.31 | C11: 5
A12: ='6. Weighted Summary'!A11 -> pdftotext + docling | B12: =IFERROR('6. Weighted Summary'!N11,"") -> 3.29 | C12: 6
A13: ='6. Weighted Summary'!A12 -> Llamaparse | B13: =IFERROR('6. Weighted Summary'!N12,"") -> 4.02 | C13: 1
A14: ='6. Weighted Summary'!A13 -> Azure Document Intelligence | B14: =IFERROR('6. Weighted Summary'!N13,"") -> 3.36 | C14: 3
